==== Logs from pod/fastapi-deployment-7965d9ff6c-nvt7g ====
INFO:     Started server process [1]
INFO:     Waiting for application startup.
INFO:     Application startup complete.
INFO:     Uvicorn running on http://0.0.0.0:5000 (Press CTRL+C to quit)
INFO:     10.42.0.42:46876 - "GET / HTTP/1.1" 200 OK
INFO:     10.42.0.42:37798 - "GET /users HTTP/1.1" 200 OK
INFO:     10.42.0.42:37302 - "DELETE /1 HTTP/1.1" 204 No Content
ERROR:    Exception in ASGI application
Traceback (most recent call last):
  File "/usr/local/lib/python3.8/site-packages/uvicorn/protocols/http/h11_impl.py", line 369, in run_asgi
    result = await app(self.scope, self.receive, self.send)
  File "/usr/local/lib/python3.8/site-packages/uvicorn/middleware/proxy_headers.py", line 59, in __call__
    return await self.app(scope, receive, send)
  File "/usr/local/lib/python3.8/site-packages/fastapi/applications.py", line 199, in __call__
    await super().__call__(scope, receive, send)
  File "/usr/local/lib/python3.8/site-packages/starlette/applications.py", line 112, in __call__
    await self.middleware_stack(scope, receive, send)
  File "/usr/local/lib/python3.8/site-packages/starlette/middleware/errors.py", line 181, in __call__
    raise exc from None
  File "/usr/local/lib/python3.8/site-packages/starlette/middleware/errors.py", line 159, in __call__
    await self.app(scope, receive, _send)
  File "/usr/local/lib/python3.8/site-packages/starlette/exceptions.py", line 82, in __call__
    raise exc from None
  File "/usr/local/lib/python3.8/site-packages/starlette/exceptions.py", line 71, in __call__
    await self.app(scope, receive, sender)
  File "/usr/local/lib/python3.8/site-packages/starlette/routing.py", line 580, in __call__
    await route.handle(scope, receive, send)
  File "/usr/local/lib/python3.8/site-packages/starlette/routing.py", line 241, in handle
    await self.app(scope, receive, send)
  File "/usr/local/lib/python3.8/site-packages/starlette/routing.py", line 55, in app
    await response(scope, receive, send)
  File "/usr/local/lib/python3.8/site-packages/starlette/responses.py", line 143, in __call__
    await send({"type": "http.response.body", "body": self.body})
  File "/usr/local/lib/python3.8/site-packages/starlette/exceptions.py", line 68, in sender
    await send(message)
  File "/usr/local/lib/python3.8/site-packages/starlette/middleware/errors.py", line 156, in _send
    await send(message)
  File "/usr/local/lib/python3.8/site-packages/uvicorn/protocols/http/h11_impl.py", line 465, in send
    output = self.conn.send(event)
  File "/usr/local/lib/python3.8/site-packages/h11/_connection.py", line 468, in send
    data_list = self.send_with_data_passthrough(event)
  File "/usr/local/lib/python3.8/site-packages/h11/_connection.py", line 501, in send_with_data_passthrough
    writer(event, data_list.append)
  File "/usr/local/lib/python3.8/site-packages/h11/_writers.py", line 58, in __call__
    self.send_data(event.data, write)
  File "/usr/local/lib/python3.8/site-packages/h11/_writers.py", line 78, in send_data
    raise LocalProtocolError("Too much data for declared Content-Length")
h11._util.LocalProtocolError: Too much data for declared Content-Length
INFO:     10.42.0.42:60076 - "POST / HTTP/1.1" 200 OK
INFO:     10.42.0.42:60948 - "POST / HTTP/1.1" 200 OK
INFO:     10.42.0.42:44418 - "GET /users/coount HTTP/1.1" 500 Internal Server Error
ERROR:    Exception in ASGI application
Traceback (most recent call last):
  File "/usr/local/lib/python3.8/site-packages/uvicorn/protocols/http/h11_impl.py", line 369, in run_asgi
    result = await app(self.scope, self.receive, self.send)
  File "/usr/local/lib/python3.8/site-packages/uvicorn/middleware/proxy_headers.py", line 59, in __call__
    return await self.app(scope, receive, send)
  File "/usr/local/lib/python3.8/site-packages/fastapi/applications.py", line 199, in __call__
    await super().__call__(scope, receive, send)
  File "/usr/local/lib/python3.8/site-packages/starlette/applications.py", line 112, in __call__
    await self.middleware_stack(scope, receive, send)
  File "/usr/local/lib/python3.8/site-packages/starlette/middleware/errors.py", line 181, in __call__
    raise exc from None
  File "/usr/local/lib/python3.8/site-packages/starlette/middleware/errors.py", line 159, in __call__
    await self.app(scope, receive, _send)
  File "/usr/local/lib/python3.8/site-packages/starlette/exceptions.py", line 82, in __call__
    raise exc from None
  File "/usr/local/lib/python3.8/site-packages/starlette/exceptions.py", line 71, in __call__
    await self.app(scope, receive, sender)
  File "/usr/local/lib/python3.8/site-packages/starlette/routing.py", line 580, in __call__
    await route.handle(scope, receive, send)
  File "/usr/local/lib/python3.8/site-packages/starlette/routing.py", line 241, in handle
    await self.app(scope, receive, send)
  File "/usr/local/lib/python3.8/site-packages/starlette/routing.py", line 52, in app
    response = await func(request)
  File "/usr/local/lib/python3.8/site-packages/fastapi/routing.py", line 216, in app
    raw_response = await run_endpoint_function(
  File "/usr/local/lib/python3.8/site-packages/fastapi/routing.py", line 151, in run_endpoint_function
    return await run_in_threadpool(dependant.call, **values)
  File "/usr/local/lib/python3.8/site-packages/starlette/concurrency.py", line 40, in run_in_threadpool
    return await loop.run_in_executor(None, func, *args)
  File "/usr/local/lib/python3.8/concurrent/futures/thread.py", line 57, in run
    result = self.fn(*self.args, **self.kwargs)
  File "/app/./routes/user.py", line 42, in get_user
    return conn.execute(users.select().where(users.c.id == id)).first()
  File "/usr/local/lib/python3.8/site-packages/sqlalchemy/engine/base.py", line 1262, in execute
    return meth(self, multiparams, params, _EMPTY_EXECUTION_OPTS)
  File "/usr/local/lib/python3.8/site-packages/sqlalchemy/sql/elements.py", line 323, in _execute_on_connection
    return connection._execute_clauseelement(
  File "/usr/local/lib/python3.8/site-packages/sqlalchemy/engine/base.py", line 1451, in _execute_clauseelement
    ret = self._execute_context(
  File "/usr/local/lib/python3.8/site-packages/sqlalchemy/engine/base.py", line 1813, in _execute_context
    self._handle_dbapi_exception(
  File "/usr/local/lib/python3.8/site-packages/sqlalchemy/engine/base.py", line 1994, in _handle_dbapi_exception
    util.raise_(
  File "/usr/local/lib/python3.8/site-packages/sqlalchemy/util/compat.py", line 207, in raise_
    raise exception
  File "/usr/local/lib/python3.8/site-packages/sqlalchemy/engine/base.py", line 1770, in _execute_context
    self.dialect.do_execute(
  File "/usr/local/lib/python3.8/site-packages/sqlalchemy/engine/default.py", line 717, in do_execute
    cursor.execute(statement, parameters)
sqlalchemy.exc.DataError: (psycopg2.errors.InvalidTextRepresentation) invalid input syntax for type integer: "coount"
LINE 3: WHERE users.id = 'coount'
                         ^

[SQL: SELECT users.id, users.name, users.email, users.password 
FROM users 
WHERE users.id = %(id_1)s]
[parameters: {'id_1': 'coount'}]
(Background on this error at: http://sqlalche.me/e/14/9h9h)
INFO:     10.42.0.42:44420 - "GET /user/coount HTTP/1.1" 404 Not Found
INFO:     10.42.0.42:44420 - "GET /user/coount HTTP/1.1" 404 Not Found
INFO:     10.42.0.42:43630 - "GET /users/count HTTP/1.1" 200 OK
INFO:     10.42.0.42:34802 - "GET /users/count HTTP/1.1" 200 OK
INFO:     10.42.0.42:34802 - "GET /users/count HTTP/1.1" 200 OK
INFO:     10.42.0.42:34802 - "GET /users/count HTTP/1.1" 200 OK
INFO:     10.42.0.42:34802 - "GET /users/count HTTP/1.1" 200 OK
INFO:     10.42.0.42:51122 - "GET /users/docs HTTP/1.1" 500 Internal Server Error
ERROR:    Exception in ASGI application
Traceback (most recent call last):
  File "/usr/local/lib/python3.8/site-packages/uvicorn/protocols/http/h11_impl.py", line 369, in run_asgi
    result = await app(self.scope, self.receive, self.send)
  File "/usr/local/lib/python3.8/site-packages/uvicorn/middleware/proxy_headers.py", line 59, in __call__
    return await self.app(scope, receive, send)
  File "/usr/local/lib/python3.8/site-packages/fastapi/applications.py", line 199, in __call__
    await super().__call__(scope, receive, send)
  File "/usr/local/lib/python3.8/site-packages/starlette/applications.py", line 112, in __call__
    await self.middleware_stack(scope, receive, send)
  File "/usr/local/lib/python3.8/site-packages/starlette/middleware/errors.py", line 181, in __call__
    raise exc from None
  File "/usr/local/lib/python3.8/site-packages/starlette/middleware/errors.py", line 159, in __call__
    await self.app(scope, receive, _send)
  File "/usr/local/lib/python3.8/site-packages/starlette/exceptions.py", line 82, in __call__
    raise exc from None
  File "/usr/local/lib/python3.8/site-packages/starlette/exceptions.py", line 71, in __call__
    await self.app(scope, receive, sender)
  File "/usr/local/lib/python3.8/site-packages/starlette/routing.py", line 580, in __call__
    await route.handle(scope, receive, send)
  File "/usr/local/lib/python3.8/site-packages/starlette/routing.py", line 241, in handle
    await self.app(scope, receive, send)
  File "/usr/local/lib/python3.8/site-packages/starlette/routing.py", line 52, in app
    response = await func(request)
  File "/usr/local/lib/python3.8/site-packages/fastapi/routing.py", line 216, in app
    raw_response = await run_endpoint_function(
  File "/usr/local/lib/python3.8/site-packages/fastapi/routing.py", line 151, in run_endpoint_function
    return await run_in_threadpool(dependant.call, **values)
  File "/usr/local/lib/python3.8/site-packages/starlette/concurrency.py", line 40, in run_in_threadpool
    return await loop.run_in_executor(None, func, *args)
  File "/usr/local/lib/python3.8/concurrent/futures/thread.py", line 57, in run
    result = self.fn(*self.args, **self.kwargs)
  File "/app/./routes/user.py", line 42, in get_user
    return conn.execute(users.select().where(users.c.id == id)).first()
  File "/usr/local/lib/python3.8/site-packages/sqlalchemy/engine/base.py", line 1262, in execute
    return meth(self, multiparams, params, _EMPTY_EXECUTION_OPTS)
  File "/usr/local/lib/python3.8/site-packages/sqlalchemy/sql/elements.py", line 323, in _execute_on_connection
    return connection._execute_clauseelement(
  File "/usr/local/lib/python3.8/site-packages/sqlalchemy/engine/base.py", line 1451, in _execute_clauseelement
    ret = self._execute_context(
  File "/usr/local/lib/python3.8/site-packages/sqlalchemy/engine/base.py", line 1813, in _execute_context
    self._handle_dbapi_exception(
  File "/usr/local/lib/python3.8/site-packages/sqlalchemy/engine/base.py", line 1994, in _handle_dbapi_exception
    util.raise_(
  File "/usr/local/lib/python3.8/site-packages/sqlalchemy/util/compat.py", line 207, in raise_
    raise exception
  File "/usr/local/lib/python3.8/site-packages/sqlalchemy/engine/base.py", line 1770, in _execute_context
    self.dialect.do_execute(
  File "/usr/local/lib/python3.8/site-packages/sqlalchemy/engine/default.py", line 717, in do_execute
    cursor.execute(statement, parameters)
sqlalchemy.exc.DataError: (psycopg2.errors.InvalidTextRepresentation) invalid input syntax for type integer: "docs"
LINE 3: WHERE users.id = 'docs'
                         ^

[SQL: SELECT users.id, users.name, users.email, users.password 
FROM users 
WHERE users.id = %(id_1)s]
[parameters: {'id_1': 'docs'}]
(Background on this error at: http://sqlalche.me/e/14/9h9h)
INFO:     10.42.0.42:39218 - "POST /docs?id=4&name=Frank&email=frank123@gmail.com&password=password HTTP/1.1" 405 Method Not Allowed
INFO:     10.42.0.42:38176 - "GET /users/count HTTP/1.1" 200 OK
INFO:     10.42.0.42:49936 - "GET /openapi.json HTTP/1.1" 200 OK
INFO:     10.42.0.42:46660 - "GET /users HTTP/1.1" 200 OK
INFO:     10.42.0.42:46676 - "GET /users HTTP/1.1" 200 OK
INFO:     10.42.0.42:46676 - "GET /users HTTP/1.1" 200 OK



==== Logs from pod/fastapi-deployment-7965d9ff6c-zlvl2 ====
INFO:     Started server process [1]
INFO:     Waiting for application startup.
INFO:     Application startup complete.
INFO:     Uvicorn running on http://0.0.0.0:5000 (Press CTRL+C to quit)
INFO:     10.42.0.42:39326 - "GET /favicon.ico HTTP/1.1" 405 Method Not Allowed
INFO:     10.42.0.42:58128 - "GET /users HTTP/1.1" 200 OK
INFO:     10.42.0.42:50136 - "GET /openapi.json HTTP/1.1" 200 OK
INFO:     10.42.0.42:43896 - "POST / HTTP/1.1" 200 OK
INFO:     10.42.0.42:39682 - "GET /users/ HTTP/1.1" 307 Temporary Redirect
INFO:     10.42.0.42:39682 - "GET /users HTTP/1.1" 200 OK
INFO:     10.42.0.42:40396 - "GET /user/coount HTTP/1.1" 404 Not Found
INFO:     10.42.0.42:40396 - "GET /user/coount HTTP/1.1" 404 Not Found
INFO:     10.42.0.42:40396 - "GET /user/coount HTTP/1.1" 404 Not Found
INFO:     10.42.0.42:45338 - "GET /users/count HTTP/1.1" 200 OK
INFO:     10.42.0.42:45338 - "GET /users/count HTTP/1.1" 200 OK
INFO:     10.42.0.42:45338 - "GET /users/count HTTP/1.1" 200 OK
INFO:     10.42.0.42:45338 - "GET /users/count HTTP/1.1" 200 OK
INFO:     10.42.0.42:46364 - "GET /users/docs HTTP/1.1" 500 Internal Server Error
ERROR:    Exception in ASGI application
Traceback (most recent call last):
  File "/usr/local/lib/python3.8/site-packages/uvicorn/protocols/http/h11_impl.py", line 369, in run_asgi
    result = await app(self.scope, self.receive, self.send)
  File "/usr/local/lib/python3.8/site-packages/uvicorn/middleware/proxy_headers.py", line 59, in __call__
    return await self.app(scope, receive, send)
  File "/usr/local/lib/python3.8/site-packages/fastapi/applications.py", line 199, in __call__
    await super().__call__(scope, receive, send)
  File "/usr/local/lib/python3.8/site-packages/starlette/applications.py", line 112, in __call__
    await self.middleware_stack(scope, receive, send)
  File "/usr/local/lib/python3.8/site-packages/starlette/middleware/errors.py", line 181, in __call__
    raise exc from None
  File "/usr/local/lib/python3.8/site-packages/starlette/middleware/errors.py", line 159, in __call__
    await self.app(scope, receive, _send)
  File "/usr/local/lib/python3.8/site-packages/starlette/exceptions.py", line 82, in __call__
    raise exc from None
  File "/usr/local/lib/python3.8/site-packages/starlette/exceptions.py", line 71, in __call__
    await self.app(scope, receive, sender)
  File "/usr/local/lib/python3.8/site-packages/starlette/routing.py", line 580, in __call__
    await route.handle(scope, receive, send)
  File "/usr/local/lib/python3.8/site-packages/starlette/routing.py", line 241, in handle
    await self.app(scope, receive, send)
  File "/usr/local/lib/python3.8/site-packages/starlette/routing.py", line 52, in app
    response = await func(request)
  File "/usr/local/lib/python3.8/site-packages/fastapi/routing.py", line 216, in app
    raw_response = await run_endpoint_function(
  File "/usr/local/lib/python3.8/site-packages/fastapi/routing.py", line 151, in run_endpoint_function
    return await run_in_threadpool(dependant.call, **values)
  File "/usr/local/lib/python3.8/site-packages/starlette/concurrency.py", line 40, in run_in_threadpool
    return await loop.run_in_executor(None, func, *args)
  File "/usr/local/lib/python3.8/concurrent/futures/thread.py", line 57, in run
    result = self.fn(*self.args, **self.kwargs)
  File "/app/./routes/user.py", line 42, in get_user
    return conn.execute(users.select().where(users.c.id == id)).first()
  File "/usr/local/lib/python3.8/site-packages/sqlalchemy/engine/base.py", line 1262, in execute
    return meth(self, multiparams, params, _EMPTY_EXECUTION_OPTS)
  File "/usr/local/lib/python3.8/site-packages/sqlalchemy/sql/elements.py", line 323, in _execute_on_connection
    return connection._execute_clauseelement(
  File "/usr/local/lib/python3.8/site-packages/sqlalchemy/engine/base.py", line 1451, in _execute_clauseelement
    ret = self._execute_context(
  File "/usr/local/lib/python3.8/site-packages/sqlalchemy/engine/base.py", line 1813, in _execute_context
    self._handle_dbapi_exception(
  File "/usr/local/lib/python3.8/site-packages/sqlalchemy/engine/base.py", line 1994, in _handle_dbapi_exception
    util.raise_(
  File "/usr/local/lib/python3.8/site-packages/sqlalchemy/util/compat.py", line 207, in raise_
    raise exception
  File "/usr/local/lib/python3.8/site-packages/sqlalchemy/engine/base.py", line 1770, in _execute_context
    self.dialect.do_execute(
  File "/usr/local/lib/python3.8/site-packages/sqlalchemy/engine/default.py", line 717, in do_execute
    cursor.execute(statement, parameters)
sqlalchemy.exc.DataError: (psycopg2.errors.InvalidTextRepresentation) invalid input syntax for type integer: "docs"
LINE 3: WHERE users.id = 'docs'
                         ^

[SQL: SELECT users.id, users.name, users.email, users.password 
FROM users 
WHERE users.id = %(id_1)s]
[parameters: {'id_1': 'docs'}]
(Background on this error at: http://sqlalche.me/e/14/9h9h)
INFO:     10.42.0.42:46368 - "GET /openapi.json HTTP/1.1" 200 OK
INFO:     10.42.0.42:44352 - "GET /docs HTTP/1.1" 200 OK
INFO:     10.42.0.42:44352 - "GET /docs HTTP/1.1" 200 OK
INFO:     10.42.0.42:44518 - "GET /users/count HTTP/1.1" 200 OK
INFO:     10.42.0.42:48722 - "GET /users HTTP/1.1" 200 OK
INFO:     10.42.0.42:48722 - "GET /users HTTP/1.1" 200 OK



==== Logs from pod/fastapi-deployment-7965d9ff6c-zplr8 ====
INFO:     Started server process [1]
INFO:     Waiting for application startup.
INFO:     Application startup complete.
INFO:     Uvicorn running on http://0.0.0.0:5000 (Press CTRL+C to quit)
INFO:     10.42.0.42:44884 - "GET / HTTP/1.1" 200 OK
INFO:     10.42.0.42:55354 - "GET /docs HTTP/1.1" 200 OK
INFO:     10.42.0.42:36658 - "DELETE /1 HTTP/1.1" 500 Internal Server Error
ERROR:    Exception in ASGI application
Traceback (most recent call last):
  File "/usr/local/lib/python3.8/site-packages/uvicorn/protocols/http/h11_impl.py", line 369, in run_asgi
    result = await app(self.scope, self.receive, self.send)
  File "/usr/local/lib/python3.8/site-packages/uvicorn/middleware/proxy_headers.py", line 59, in __call__
    return await self.app(scope, receive, send)
  File "/usr/local/lib/python3.8/site-packages/fastapi/applications.py", line 199, in __call__
    await super().__call__(scope, receive, send)
  File "/usr/local/lib/python3.8/site-packages/starlette/applications.py", line 112, in __call__
    await self.middleware_stack(scope, receive, send)
  File "/usr/local/lib/python3.8/site-packages/starlette/middleware/errors.py", line 181, in __call__
    raise exc from None
  File "/usr/local/lib/python3.8/site-packages/starlette/middleware/errors.py", line 159, in __call__
    await self.app(scope, receive, _send)
  File "/usr/local/lib/python3.8/site-packages/starlette/exceptions.py", line 82, in __call__
    raise exc from None
  File "/usr/local/lib/python3.8/site-packages/starlette/exceptions.py", line 71, in __call__
    await self.app(scope, receive, sender)
  File "/usr/local/lib/python3.8/site-packages/starlette/routing.py", line 580, in __call__
    await route.handle(scope, receive, send)
  File "/usr/local/lib/python3.8/site-packages/starlette/routing.py", line 241, in handle
    await self.app(scope, receive, send)
  File "/usr/local/lib/python3.8/site-packages/starlette/routing.py", line 52, in app
    response = await func(request)
  File "/usr/local/lib/python3.8/site-packages/fastapi/routing.py", line 216, in app
    raw_response = await run_endpoint_function(
  File "/usr/local/lib/python3.8/site-packages/fastapi/routing.py", line 151, in run_endpoint_function
    return await run_in_threadpool(dependant.call, **values)
  File "/usr/local/lib/python3.8/site-packages/starlette/concurrency.py", line 40, in run_in_threadpool
    return await loop.run_in_executor(None, func, *args)
  File "/usr/local/lib/python3.8/concurrent/futures/thread.py", line 57, in run
    result = self.fn(*self.args, **self.kwargs)
  File "/app/./routes/user.py", line 67, in delete_user
    conn.execute(users.delete().where(users.c.id == id))
  File "/usr/local/lib/python3.8/site-packages/sqlalchemy/engine/base.py", line 1262, in execute
    return meth(self, multiparams, params, _EMPTY_EXECUTION_OPTS)
  File "/usr/local/lib/python3.8/site-packages/sqlalchemy/sql/elements.py", line 323, in _execute_on_connection
    return connection._execute_clauseelement(
  File "/usr/local/lib/python3.8/site-packages/sqlalchemy/engine/base.py", line 1451, in _execute_clauseelement
    ret = self._execute_context(
  File "/usr/local/lib/python3.8/site-packages/sqlalchemy/engine/base.py", line 1813, in _execute_context
    self._handle_dbapi_exception(
  File "/usr/local/lib/python3.8/site-packages/sqlalchemy/engine/base.py", line 1994, in _handle_dbapi_exception
    util.raise_(
  File "/usr/local/lib/python3.8/site-packages/sqlalchemy/util/compat.py", line 207, in raise_
    raise exception
  File "/usr/local/lib/python3.8/site-packages/sqlalchemy/engine/base.py", line 1770, in _execute_context
    self.dialect.do_execute(
  File "/usr/local/lib/python3.8/site-packages/sqlalchemy/engine/default.py", line 717, in do_execute
    cursor.execute(statement, parameters)
sqlalchemy.exc.ProgrammingError: (psycopg2.errors.UndefinedTable) relation "users" does not exist
LINE 1: DELETE FROM users WHERE users.id = 1
                    ^

[SQL: DELETE FROM users WHERE users.id = %(id_1)s]
[parameters: {'id_1': 1}]
(Background on this error at: http://sqlalche.me/e/14/f405)
INFO:     10.42.0.42:45080 - "POST / HTTP/1.1" 500 Internal Server Error
ERROR:    Exception in ASGI application
Traceback (most recent call last):
  File "/usr/local/lib/python3.8/site-packages/uvicorn/protocols/http/h11_impl.py", line 369, in run_asgi
    result = await app(self.scope, self.receive, self.send)
  File "/usr/local/lib/python3.8/site-packages/uvicorn/middleware/proxy_headers.py", line 59, in __call__
    return await self.app(scope, receive, send)
  File "/usr/local/lib/python3.8/site-packages/fastapi/applications.py", line 199, in __call__
    await super().__call__(scope, receive, send)
  File "/usr/local/lib/python3.8/site-packages/starlette/applications.py", line 112, in __call__
    await self.middleware_stack(scope, receive, send)
  File "/usr/local/lib/python3.8/site-packages/starlette/middleware/errors.py", line 181, in __call__
    raise exc from None
  File "/usr/local/lib/python3.8/site-packages/starlette/middleware/errors.py", line 159, in __call__
    await self.app(scope, receive, _send)
  File "/usr/local/lib/python3.8/site-packages/starlette/exceptions.py", line 82, in __call__
    raise exc from None
  File "/usr/local/lib/python3.8/site-packages/starlette/exceptions.py", line 71, in __call__
    await self.app(scope, receive, sender)
  File "/usr/local/lib/python3.8/site-packages/starlette/routing.py", line 580, in __call__
    await route.handle(scope, receive, send)
  File "/usr/local/lib/python3.8/site-packages/starlette/routing.py", line 241, in handle
    await self.app(scope, receive, send)
  File "/usr/local/lib/python3.8/site-packages/starlette/routing.py", line 52, in app
    response = await func(request)
  File "/usr/local/lib/python3.8/site-packages/fastapi/routing.py", line 216, in app
    raw_response = await run_endpoint_function(
  File "/usr/local/lib/python3.8/site-packages/fastapi/routing.py", line 151, in run_endpoint_function
    return await run_in_threadpool(dependant.call, **values)
  File "/usr/local/lib/python3.8/site-packages/starlette/concurrency.py", line 40, in run_in_threadpool
    return await loop.run_in_executor(None, func, *args)
  File "/usr/local/lib/python3.8/concurrent/futures/thread.py", line 57, in run
    result = self.fn(*self.args, **self.kwargs)
  File "/app/./routes/user.py", line 49, in create_user
    result = conn.execute(users.insert().values(new_user))
  File "/usr/local/lib/python3.8/site-packages/sqlalchemy/engine/base.py", line 1262, in execute
    return meth(self, multiparams, params, _EMPTY_EXECUTION_OPTS)
  File "/usr/local/lib/python3.8/site-packages/sqlalchemy/sql/elements.py", line 323, in _execute_on_connection
    return connection._execute_clauseelement(
  File "/usr/local/lib/python3.8/site-packages/sqlalchemy/engine/base.py", line 1451, in _execute_clauseelement
    ret = self._execute_context(
  File "/usr/local/lib/python3.8/site-packages/sqlalchemy/engine/base.py", line 1813, in _execute_context
    self._handle_dbapi_exception(
  File "/usr/local/lib/python3.8/site-packages/sqlalchemy/engine/base.py", line 1994, in _handle_dbapi_exception
    util.raise_(
  File "/usr/local/lib/python3.8/site-packages/sqlalchemy/util/compat.py", line 207, in raise_
    raise exception
  File "/usr/local/lib/python3.8/site-packages/sqlalchemy/engine/base.py", line 1770, in _execute_context
    self.dialect.do_execute(
  File "/usr/local/lib/python3.8/site-packages/sqlalchemy/engine/default.py", line 717, in do_execute
    cursor.execute(statement, parameters)
sqlalchemy.exc.ProgrammingError: (psycopg2.errors.UndefinedTable) relation "users" does not exist
LINE 1: INSERT INTO users (name, email, password) VALUES ('Alice', '...
                    ^

[SQL: INSERT INTO users (name, email, password) VALUES (%(name)s, %(email)s, %(password)s) RETURNING users.id]
[parameters: {'name': 'Alice', 'email': 'Alice1@gmail.com', 'password': b'gAAAAABn9UG9rXCLi5_wkbpXWzITGNanwkfGASbUaRQBeiIGzM9JolmdYPvk5d8iR9NIqBI-WXnokt0b5kG35NBazzNTfpJNcA=='}]
(Background on this error at: http://sqlalche.me/e/14/f405)
INFO:     10.42.0.42:48854 - "GET /users HTTP/1.1" 500 Internal Server Error
ERROR:    Exception in ASGI application
Traceback (most recent call last):
  File "/usr/local/lib/python3.8/site-packages/uvicorn/protocols/http/h11_impl.py", line 369, in run_asgi
    result = await app(self.scope, self.receive, self.send)
  File "/usr/local/lib/python3.8/site-packages/uvicorn/middleware/proxy_headers.py", line 59, in __call__
    return await self.app(scope, receive, send)
  File "/usr/local/lib/python3.8/site-packages/fastapi/applications.py", line 199, in __call__
    await super().__call__(scope, receive, send)
  File "/usr/local/lib/python3.8/site-packages/starlette/applications.py", line 112, in __call__
    await self.middleware_stack(scope, receive, send)
  File "/usr/local/lib/python3.8/site-packages/starlette/middleware/errors.py", line 181, in __call__
    raise exc from None
  File "/usr/local/lib/python3.8/site-packages/starlette/middleware/errors.py", line 159, in __call__
    await self.app(scope, receive, _send)
  File "/usr/local/lib/python3.8/site-packages/starlette/exceptions.py", line 82, in __call__
    raise exc from None
  File "/usr/local/lib/python3.8/site-packages/starlette/exceptions.py", line 71, in __call__
    await self.app(scope, receive, sender)
  File "/usr/local/lib/python3.8/site-packages/starlette/routing.py", line 580, in __call__
    await route.handle(scope, receive, send)
  File "/usr/local/lib/python3.8/site-packages/starlette/routing.py", line 241, in handle
    await self.app(scope, receive, send)
  File "/usr/local/lib/python3.8/site-packages/starlette/routing.py", line 52, in app
    response = await func(request)
  File "/usr/local/lib/python3.8/site-packages/fastapi/routing.py", line 216, in app
    raw_response = await run_endpoint_function(
  File "/usr/local/lib/python3.8/site-packages/fastapi/routing.py", line 151, in run_endpoint_function
    return await run_in_threadpool(dependant.call, **values)
  File "/usr/local/lib/python3.8/site-packages/starlette/concurrency.py", line 40, in run_in_threadpool
    return await loop.run_in_executor(None, func, *args)
  File "/usr/local/lib/python3.8/concurrent/futures/thread.py", line 57, in run
    result = self.fn(*self.args, **self.kwargs)
  File "/app/./routes/user.py", line 26, in get_users
    return conn.execute(users.select()).fetchall()
  File "/usr/local/lib/python3.8/site-packages/sqlalchemy/engine/base.py", line 1262, in execute
    return meth(self, multiparams, params, _EMPTY_EXECUTION_OPTS)
  File "/usr/local/lib/python3.8/site-packages/sqlalchemy/sql/elements.py", line 323, in _execute_on_connection
    return connection._execute_clauseelement(
  File "/usr/local/lib/python3.8/site-packages/sqlalchemy/engine/base.py", line 1451, in _execute_clauseelement
    ret = self._execute_context(
  File "/usr/local/lib/python3.8/site-packages/sqlalchemy/engine/base.py", line 1813, in _execute_context
    self._handle_dbapi_exception(
  File "/usr/local/lib/python3.8/site-packages/sqlalchemy/engine/base.py", line 1994, in _handle_dbapi_exception
    util.raise_(
  File "/usr/local/lib/python3.8/site-packages/sqlalchemy/util/compat.py", line 207, in raise_
    raise exception
  File "/usr/local/lib/python3.8/site-packages/sqlalchemy/engine/base.py", line 1770, in _execute_context
    self.dialect.do_execute(
  File "/usr/local/lib/python3.8/site-packages/sqlalchemy/engine/default.py", line 717, in do_execute
    cursor.execute(statement, parameters)
sqlalchemy.exc.ProgrammingError: (psycopg2.errors.UndefinedTable) relation "users" does not exist
LINE 2: FROM users
             ^

[SQL: SELECT users.id, users.name, users.email, users.password 
FROM users]
(Background on this error at: http://sqlalche.me/e/14/f405)
INFO:     10.42.0.42:49340 - "GET /users/coount HTTP/1.1" 500 Internal Server Error
ERROR:    Exception in ASGI application
Traceback (most recent call last):
  File "/usr/local/lib/python3.8/site-packages/uvicorn/protocols/http/h11_impl.py", line 369, in run_asgi
    result = await app(self.scope, self.receive, self.send)
  File "/usr/local/lib/python3.8/site-packages/uvicorn/middleware/proxy_headers.py", line 59, in __call__
    return await self.app(scope, receive, send)
  File "/usr/local/lib/python3.8/site-packages/fastapi/applications.py", line 199, in __call__
    await super().__call__(scope, receive, send)
  File "/usr/local/lib/python3.8/site-packages/starlette/applications.py", line 112, in __call__
    await self.middleware_stack(scope, receive, send)
  File "/usr/local/lib/python3.8/site-packages/starlette/middleware/errors.py", line 181, in __call__
    raise exc from None
  File "/usr/local/lib/python3.8/site-packages/starlette/middleware/errors.py", line 159, in __call__
    await self.app(scope, receive, _send)
  File "/usr/local/lib/python3.8/site-packages/starlette/exceptions.py", line 82, in __call__
    raise exc from None
  File "/usr/local/lib/python3.8/site-packages/starlette/exceptions.py", line 71, in __call__
    await self.app(scope, receive, sender)
  File "/usr/local/lib/python3.8/site-packages/starlette/routing.py", line 580, in __call__
    await route.handle(scope, receive, send)
  File "/usr/local/lib/python3.8/site-packages/starlette/routing.py", line 241, in handle
    await self.app(scope, receive, send)
  File "/usr/local/lib/python3.8/site-packages/starlette/routing.py", line 52, in app
    response = await func(request)
  File "/usr/local/lib/python3.8/site-packages/fastapi/routing.py", line 216, in app
    raw_response = await run_endpoint_function(
  File "/usr/local/lib/python3.8/site-packages/fastapi/routing.py", line 151, in run_endpoint_function
    return await run_in_threadpool(dependant.call, **values)
  File "/usr/local/lib/python3.8/site-packages/starlette/concurrency.py", line 40, in run_in_threadpool
    return await loop.run_in_executor(None, func, *args)
  File "/usr/local/lib/python3.8/concurrent/futures/thread.py", line 57, in run
    result = self.fn(*self.args, **self.kwargs)
  File "/app/./routes/user.py", line 42, in get_user
    return conn.execute(users.select().where(users.c.id == id)).first()
  File "/usr/local/lib/python3.8/site-packages/sqlalchemy/engine/base.py", line 1262, in execute
    return meth(self, multiparams, params, _EMPTY_EXECUTION_OPTS)
  File "/usr/local/lib/python3.8/site-packages/sqlalchemy/sql/elements.py", line 323, in _execute_on_connection
    return connection._execute_clauseelement(
  File "/usr/local/lib/python3.8/site-packages/sqlalchemy/engine/base.py", line 1451, in _execute_clauseelement
    ret = self._execute_context(
  File "/usr/local/lib/python3.8/site-packages/sqlalchemy/engine/base.py", line 1813, in _execute_context
    self._handle_dbapi_exception(
  File "/usr/local/lib/python3.8/site-packages/sqlalchemy/engine/base.py", line 1994, in _handle_dbapi_exception
    util.raise_(
  File "/usr/local/lib/python3.8/site-packages/sqlalchemy/util/compat.py", line 207, in raise_
    raise exception
  File "/usr/local/lib/python3.8/site-packages/sqlalchemy/engine/base.py", line 1770, in _execute_context
    self.dialect.do_execute(
  File "/usr/local/lib/python3.8/site-packages/sqlalchemy/engine/default.py", line 717, in do_execute
    cursor.execute(statement, parameters)
sqlalchemy.exc.ProgrammingError: (psycopg2.errors.UndefinedTable) relation "users" does not exist
LINE 2: FROM users 
             ^

[SQL: SELECT users.id, users.name, users.email, users.password 
FROM users 
WHERE users.id = %(id_1)s]
[parameters: {'id_1': 'coount'}]
(Background on this error at: http://sqlalche.me/e/14/f405)
INFO:     10.42.0.42:43358 - "GET /user/coount HTTP/1.1" 404 Not Found
INFO:     10.42.0.42:43358 - "GET /user/coount HTTP/1.1" 404 Not Found
INFO:     10.42.0.42:59602 - "GET /users/count HTTP/1.1" 500 Internal Server Error
ERROR:    Exception in ASGI application
Traceback (most recent call last):
  File "/usr/local/lib/python3.8/site-packages/uvicorn/protocols/http/h11_impl.py", line 369, in run_asgi
    result = await app(self.scope, self.receive, self.send)
  File "/usr/local/lib/python3.8/site-packages/uvicorn/middleware/proxy_headers.py", line 59, in __call__
    return await self.app(scope, receive, send)
  File "/usr/local/lib/python3.8/site-packages/fastapi/applications.py", line 199, in __call__
    await super().__call__(scope, receive, send)
  File "/usr/local/lib/python3.8/site-packages/starlette/applications.py", line 112, in __call__
    await self.middleware_stack(scope, receive, send)
  File "/usr/local/lib/python3.8/site-packages/starlette/middleware/errors.py", line 181, in __call__
    raise exc from None
  File "/usr/local/lib/python3.8/site-packages/starlette/middleware/errors.py", line 159, in __call__
    await self.app(scope, receive, _send)
  File "/usr/local/lib/python3.8/site-packages/starlette/exceptions.py", line 82, in __call__
    raise exc from None
  File "/usr/local/lib/python3.8/site-packages/starlette/exceptions.py", line 71, in __call__
    await self.app(scope, receive, sender)
  File "/usr/local/lib/python3.8/site-packages/starlette/routing.py", line 580, in __call__
    await route.handle(scope, receive, send)
  File "/usr/local/lib/python3.8/site-packages/starlette/routing.py", line 241, in handle
    await self.app(scope, receive, send)
  File "/usr/local/lib/python3.8/site-packages/starlette/routing.py", line 52, in app
    response = await func(request)
  File "/usr/local/lib/python3.8/site-packages/fastapi/routing.py", line 216, in app
    raw_response = await run_endpoint_function(
  File "/usr/local/lib/python3.8/site-packages/fastapi/routing.py", line 151, in run_endpoint_function
    return await run_in_threadpool(dependant.call, **values)
  File "/usr/local/lib/python3.8/site-packages/starlette/concurrency.py", line 40, in run_in_threadpool
    return await loop.run_in_executor(None, func, *args)
  File "/usr/local/lib/python3.8/concurrent/futures/thread.py", line 57, in run
    result = self.fn(*self.args, **self.kwargs)
  File "/app/./routes/user.py", line 31, in get_users_count
    result = conn.execute(select([func.count()]).select_from(users))
  File "/usr/local/lib/python3.8/site-packages/sqlalchemy/engine/base.py", line 1262, in execute
    return meth(self, multiparams, params, _EMPTY_EXECUTION_OPTS)
  File "/usr/local/lib/python3.8/site-packages/sqlalchemy/sql/elements.py", line 323, in _execute_on_connection
    return connection._execute_clauseelement(
  File "/usr/local/lib/python3.8/site-packages/sqlalchemy/engine/base.py", line 1451, in _execute_clauseelement
    ret = self._execute_context(
  File "/usr/local/lib/python3.8/site-packages/sqlalchemy/engine/base.py", line 1813, in _execute_context
    self._handle_dbapi_exception(
  File "/usr/local/lib/python3.8/site-packages/sqlalchemy/engine/base.py", line 1994, in _handle_dbapi_exception
    util.raise_(
  File "/usr/local/lib/python3.8/site-packages/sqlalchemy/util/compat.py", line 207, in raise_
    raise exception
  File "/usr/local/lib/python3.8/site-packages/sqlalchemy/engine/base.py", line 1770, in _execute_context
    self.dialect.do_execute(
  File "/usr/local/lib/python3.8/site-packages/sqlalchemy/engine/default.py", line 717, in do_execute
    cursor.execute(statement, parameters)
sqlalchemy.exc.ProgrammingError: (psycopg2.errors.UndefinedTable) relation "users" does not exist
LINE 2: FROM users
             ^

[SQL: SELECT count(*) AS count_1 
FROM users]
(Background on this error at: http://sqlalche.me/e/14/f405)
INFO:     10.42.0.42:42116 - "GET /users/count HTTP/1.1" 500 Internal Server Error
ERROR:    Exception in ASGI application
Traceback (most recent call last):
  File "/usr/local/lib/python3.8/site-packages/uvicorn/protocols/http/h11_impl.py", line 369, in run_asgi
    result = await app(self.scope, self.receive, self.send)
  File "/usr/local/lib/python3.8/site-packages/uvicorn/middleware/proxy_headers.py", line 59, in __call__
    return await self.app(scope, receive, send)
  File "/usr/local/lib/python3.8/site-packages/fastapi/applications.py", line 199, in __call__
    await super().__call__(scope, receive, send)
  File "/usr/local/lib/python3.8/site-packages/starlette/applications.py", line 112, in __call__
    await self.middleware_stack(scope, receive, send)
  File "/usr/local/lib/python3.8/site-packages/starlette/middleware/errors.py", line 181, in __call__
    raise exc from None
  File "/usr/local/lib/python3.8/site-packages/starlette/middleware/errors.py", line 159, in __call__
    await self.app(scope, receive, _send)
  File "/usr/local/lib/python3.8/site-packages/starlette/exceptions.py", line 82, in __call__
    raise exc from None
  File "/usr/local/lib/python3.8/site-packages/starlette/exceptions.py", line 71, in __call__
    await self.app(scope, receive, sender)
  File "/usr/local/lib/python3.8/site-packages/starlette/routing.py", line 580, in __call__
    await route.handle(scope, receive, send)
  File "/usr/local/lib/python3.8/site-packages/starlette/routing.py", line 241, in handle
    await self.app(scope, receive, send)
  File "/usr/local/lib/python3.8/site-packages/starlette/routing.py", line 52, in app
    response = await func(request)
  File "/usr/local/lib/python3.8/site-packages/fastapi/routing.py", line 216, in app
    raw_response = await run_endpoint_function(
  File "/usr/local/lib/python3.8/site-packages/fastapi/routing.py", line 151, in run_endpoint_function
    return await run_in_threadpool(dependant.call, **values)
  File "/usr/local/lib/python3.8/site-packages/starlette/concurrency.py", line 40, in run_in_threadpool
    return await loop.run_in_executor(None, func, *args)
  File "/usr/local/lib/python3.8/concurrent/futures/thread.py", line 57, in run
    result = self.fn(*self.args, **self.kwargs)
  File "/app/./routes/user.py", line 31, in get_users_count
    result = conn.execute(select([func.count()]).select_from(users))
  File "/usr/local/lib/python3.8/site-packages/sqlalchemy/engine/base.py", line 1262, in execute
    return meth(self, multiparams, params, _EMPTY_EXECUTION_OPTS)
  File "/usr/local/lib/python3.8/site-packages/sqlalchemy/sql/elements.py", line 323, in _execute_on_connection
    return connection._execute_clauseelement(
  File "/usr/local/lib/python3.8/site-packages/sqlalchemy/engine/base.py", line 1451, in _execute_clauseelement
    ret = self._execute_context(
  File "/usr/local/lib/python3.8/site-packages/sqlalchemy/engine/base.py", line 1813, in _execute_context
    self._handle_dbapi_exception(
  File "/usr/local/lib/python3.8/site-packages/sqlalchemy/engine/base.py", line 1994, in _handle_dbapi_exception
    util.raise_(
  File "/usr/local/lib/python3.8/site-packages/sqlalchemy/util/compat.py", line 207, in raise_
    raise exception
  File "/usr/local/lib/python3.8/site-packages/sqlalchemy/engine/base.py", line 1770, in _execute_context
    self.dialect.do_execute(
  File "/usr/local/lib/python3.8/site-packages/sqlalchemy/engine/default.py", line 717, in do_execute
    cursor.execute(statement, parameters)
sqlalchemy.exc.ProgrammingError: (psycopg2.errors.UndefinedTable) relation "users" does not exist
LINE 2: FROM users
             ^

[SQL: SELECT count(*) AS count_1 
FROM users]
(Background on this error at: http://sqlalche.me/e/14/f405)
ERROR:    Exception in ASGI application
Traceback (most recent call last):
  File "/usr/local/lib/python3.8/site-packages/uvicorn/protocols/http/h11_impl.py", line 369, in run_asgi
    result = await app(self.scope, self.receive, self.send)
  File "/usr/local/lib/python3.8/site-packages/uvicorn/middleware/proxy_headers.py", line 59, in __call__
    return await self.app(scope, receive, send)
  File "/usr/local/lib/python3.8/site-packages/fastapi/applications.py", line 199, in __call__
    await super().__call__(scope, receive, send)
  File "/usr/local/lib/python3.8/site-packages/starlette/applications.py", line 112, in __call__
    await self.middleware_stack(scope, receive, send)
  File "/usr/local/lib/python3.8/site-packages/starlette/middleware/errors.py", line 181, in __call__
    raise exc from None
  File "/usr/local/lib/python3.8/site-packages/starlette/middleware/errors.py", line 159, in __call__
    await self.app(scope, receive, _send)
  File "/usr/local/lib/python3.8/site-packages/starlette/exceptions.py", line 82, in __call__
    raise exc from None
  File "/usr/local/lib/python3.8/site-packages/starlette/exceptions.py", line 71, in __call__
    await self.app(scope, receive, sender)
  File "/usr/local/lib/python3.8/site-packages/starlette/routing.py", line 580, in __call__
    await route.handle(scope, receive, send)
  File "/usr/local/lib/python3.8/site-packages/starlette/routing.py", line 241, in handle
    await self.app(scope, receive, send)
  File "/usr/local/lib/python3.8/site-packages/starlette/routing.py", line 52, in app
    response = await func(request)
  File "/usr/local/lib/python3.8/site-packages/fastapi/routing.py", line 216, in app
    raw_response = await run_endpoint_function(
  File "/usr/local/lib/python3.8/site-packages/fastapi/routing.py", line 151, in run_endpoint_function
    return await run_in_threadpool(dependant.call, **values)
  File "/usr/local/lib/python3.8/site-packages/starlette/concurrency.py", line 40, in run_in_threadpool
    return await loop.run_in_executor(None, func, *args)
  File "/usr/local/lib/python3.8/concurrent/futures/thread.py", line 57, in run
    result = self.fn(*self.args, **self.kwargs)
  File "/app/./routes/user.py", line 31, in get_users_count
    result = conn.execute(select([func.count()]).select_from(users))
  File "/usr/local/lib/python3.8/site-packages/sqlalchemy/engine/base.py", line 1262, in execute
    return meth(self, multiparams, params, _EMPTY_EXECUTION_OPTS)
  File "/usr/local/lib/python3.8/site-packages/sqlalchemy/sql/elements.py", line 323, in _execute_on_connection
    return connection._execute_clauseelement(
  File "/usr/local/lib/python3.8/site-packages/sqlalchemy/engine/base.py", line 1451, in _execute_clauseelement
    ret = self._execute_context(
  File "/usr/local/lib/python3.8/site-packages/sqlalchemy/engine/base.py", line 1813, in _execute_context
    self._handle_dbapi_exception(
  File "/usr/local/lib/python3.8/site-packages/sqlalchemy/engine/base.py", line 1994, in _handle_dbapi_exception
    util.raise_(
  File "/usr/local/lib/python3.8/site-packages/sqlalchemy/util/compat.py", line 207, in raise_
    raise exception
  File "/usr/local/lib/python3.8/site-packages/sqlalchemy/engine/base.py", line 1770, in _execute_context
    self.dialect.do_execute(
  File "/usr/local/lib/python3.8/site-packages/sqlalchemy/engine/default.py", line 717, in do_execute
    cursor.execute(statement, parameters)
sqlalchemy.exc.ProgrammingError: (psycopg2.errors.UndefinedTable) relation "users" does not exist
LINE 2: FROM users
             ^

[SQL: SELECT count(*) AS count_1 
FROM users]
(Background on this error at: http://sqlalche.me/e/14/f405)
INFO:     10.42.0.42:51244 - "GET /users/count HTTP/1.1" 500 Internal Server Error
INFO:     10.42.0.42:51248 - "GET /users/count HTTP/1.1" 500 Internal Server Error
ERROR:    Exception in ASGI application
Traceback (most recent call last):
  File "/usr/local/lib/python3.8/site-packages/uvicorn/protocols/http/h11_impl.py", line 369, in run_asgi
    result = await app(self.scope, self.receive, self.send)
  File "/usr/local/lib/python3.8/site-packages/uvicorn/middleware/proxy_headers.py", line 59, in __call__
    return await self.app(scope, receive, send)
  File "/usr/local/lib/python3.8/site-packages/fastapi/applications.py", line 199, in __call__
    await super().__call__(scope, receive, send)
  File "/usr/local/lib/python3.8/site-packages/starlette/applications.py", line 112, in __call__
    await self.middleware_stack(scope, receive, send)
  File "/usr/local/lib/python3.8/site-packages/starlette/middleware/errors.py", line 181, in __call__
    raise exc from None
  File "/usr/local/lib/python3.8/site-packages/starlette/middleware/errors.py", line 159, in __call__
    await self.app(scope, receive, _send)
  File "/usr/local/lib/python3.8/site-packages/starlette/exceptions.py", line 82, in __call__
    raise exc from None
  File "/usr/local/lib/python3.8/site-packages/starlette/exceptions.py", line 71, in __call__
    await self.app(scope, receive, sender)
  File "/usr/local/lib/python3.8/site-packages/starlette/routing.py", line 580, in __call__
    await route.handle(scope, receive, send)
  File "/usr/local/lib/python3.8/site-packages/starlette/routing.py", line 241, in handle
    await self.app(scope, receive, send)
  File "/usr/local/lib/python3.8/site-packages/starlette/routing.py", line 52, in app
    response = await func(request)
  File "/usr/local/lib/python3.8/site-packages/fastapi/routing.py", line 216, in app
    raw_response = await run_endpoint_function(
  File "/usr/local/lib/python3.8/site-packages/fastapi/routing.py", line 151, in run_endpoint_function
    return await run_in_threadpool(dependant.call, **values)
  File "/usr/local/lib/python3.8/site-packages/starlette/concurrency.py", line 40, in run_in_threadpool
    return await loop.run_in_executor(None, func, *args)
  File "/usr/local/lib/python3.8/concurrent/futures/thread.py", line 57, in run
    result = self.fn(*self.args, **self.kwargs)
  File "/app/./routes/user.py", line 31, in get_users_count
    result = conn.execute(select([func.count()]).select_from(users))
  File "/usr/local/lib/python3.8/site-packages/sqlalchemy/engine/base.py", line 1262, in execute
    return meth(self, multiparams, params, _EMPTY_EXECUTION_OPTS)
  File "/usr/local/lib/python3.8/site-packages/sqlalchemy/sql/elements.py", line 323, in _execute_on_connection
    return connection._execute_clauseelement(
  File "/usr/local/lib/python3.8/site-packages/sqlalchemy/engine/base.py", line 1451, in _execute_clauseelement
    ret = self._execute_context(
  File "/usr/local/lib/python3.8/site-packages/sqlalchemy/engine/base.py", line 1813, in _execute_context
    self._handle_dbapi_exception(
  File "/usr/local/lib/python3.8/site-packages/sqlalchemy/engine/base.py", line 1994, in _handle_dbapi_exception
    util.raise_(
  File "/usr/local/lib/python3.8/site-packages/sqlalchemy/util/compat.py", line 207, in raise_
    raise exception
  File "/usr/local/lib/python3.8/site-packages/sqlalchemy/engine/base.py", line 1770, in _execute_context
    self.dialect.do_execute(
  File "/usr/local/lib/python3.8/site-packages/sqlalchemy/engine/default.py", line 717, in do_execute
    cursor.execute(statement, parameters)
sqlalchemy.exc.ProgrammingError: (psycopg2.errors.UndefinedTable) relation "users" does not exist
LINE 2: FROM users
             ^

[SQL: SELECT count(*) AS count_1 
FROM users]
(Background on this error at: http://sqlalche.me/e/14/f405)
INFO:     10.42.0.42:51252 - "GET /users/count HTTP/1.1" 500 Internal Server Error
ERROR:    Exception in ASGI application
Traceback (most recent call last):
  File "/usr/local/lib/python3.8/site-packages/uvicorn/protocols/http/h11_impl.py", line 369, in run_asgi
    result = await app(self.scope, self.receive, self.send)
  File "/usr/local/lib/python3.8/site-packages/uvicorn/middleware/proxy_headers.py", line 59, in __call__
    return await self.app(scope, receive, send)
  File "/usr/local/lib/python3.8/site-packages/fastapi/applications.py", line 199, in __call__
    await super().__call__(scope, receive, send)
  File "/usr/local/lib/python3.8/site-packages/starlette/applications.py", line 112, in __call__
    await self.middleware_stack(scope, receive, send)
  File "/usr/local/lib/python3.8/site-packages/starlette/middleware/errors.py", line 181, in __call__
    raise exc from None
  File "/usr/local/lib/python3.8/site-packages/starlette/middleware/errors.py", line 159, in __call__
    await self.app(scope, receive, _send)
  File "/usr/local/lib/python3.8/site-packages/starlette/exceptions.py", line 82, in __call__
    raise exc from None
  File "/usr/local/lib/python3.8/site-packages/starlette/exceptions.py", line 71, in __call__
    await self.app(scope, receive, sender)
  File "/usr/local/lib/python3.8/site-packages/starlette/routing.py", line 580, in __call__
    await route.handle(scope, receive, send)
  File "/usr/local/lib/python3.8/site-packages/starlette/routing.py", line 241, in handle
    await self.app(scope, receive, send)
  File "/usr/local/lib/python3.8/site-packages/starlette/routing.py", line 52, in app
    response = await func(request)
  File "/usr/local/lib/python3.8/site-packages/fastapi/routing.py", line 216, in app
    raw_response = await run_endpoint_function(
  File "/usr/local/lib/python3.8/site-packages/fastapi/routing.py", line 151, in run_endpoint_function
    return await run_in_threadpool(dependant.call, **values)
  File "/usr/local/lib/python3.8/site-packages/starlette/concurrency.py", line 40, in run_in_threadpool
    return await loop.run_in_executor(None, func, *args)
  File "/usr/local/lib/python3.8/concurrent/futures/thread.py", line 57, in run
    result = self.fn(*self.args, **self.kwargs)
  File "/app/./routes/user.py", line 31, in get_users_count
    result = conn.execute(select([func.count()]).select_from(users))
  File "/usr/local/lib/python3.8/site-packages/sqlalchemy/engine/base.py", line 1262, in execute
    return meth(self, multiparams, params, _EMPTY_EXECUTION_OPTS)
  File "/usr/local/lib/python3.8/site-packages/sqlalchemy/sql/elements.py", line 323, in _execute_on_connection
    return connection._execute_clauseelement(
  File "/usr/local/lib/python3.8/site-packages/sqlalchemy/engine/base.py", line 1451, in _execute_clauseelement
    ret = self._execute_context(
  File "/usr/local/lib/python3.8/site-packages/sqlalchemy/engine/base.py", line 1813, in _execute_context
    self._handle_dbapi_exception(
  File "/usr/local/lib/python3.8/site-packages/sqlalchemy/engine/base.py", line 1994, in _handle_dbapi_exception
    util.raise_(
  File "/usr/local/lib/python3.8/site-packages/sqlalchemy/util/compat.py", line 207, in raise_
    raise exception
  File "/usr/local/lib/python3.8/site-packages/sqlalchemy/engine/base.py", line 1770, in _execute_context
    self.dialect.do_execute(
  File "/usr/local/lib/python3.8/site-packages/sqlalchemy/engine/default.py", line 717, in do_execute
    cursor.execute(statement, parameters)
sqlalchemy.exc.ProgrammingError: (psycopg2.errors.UndefinedTable) relation "users" does not exist
LINE 2: FROM users
             ^

[SQL: SELECT count(*) AS count_1 
FROM users]
(Background on this error at: http://sqlalche.me/e/14/f405)
INFO:     10.42.0.42:38344 - "GET /docs HTTP/1.1" 200 OK
INFO:     10.42.0.42:38100 - "GET / HTTP/1.1" 200 OK
INFO:     10.42.0.42:39600 - "POST /docs?id=4&name=Frank&email=frank123@gmail.com&password=password HTTP/1.1" 405 Method Not Allowed
INFO:     10.42.0.42:57542 - "GET /openapi.json HTTP/1.1" 200 OK
INFO:     10.42.0.42:41052 - "GET /users HTTP/1.1" 500 Internal Server Error
ERROR:    Exception in ASGI application
Traceback (most recent call last):
  File "/usr/local/lib/python3.8/site-packages/uvicorn/protocols/http/h11_impl.py", line 369, in run_asgi
    result = await app(self.scope, self.receive, self.send)
  File "/usr/local/lib/python3.8/site-packages/uvicorn/middleware/proxy_headers.py", line 59, in __call__
    return await self.app(scope, receive, send)
  File "/usr/local/lib/python3.8/site-packages/fastapi/applications.py", line 199, in __call__
    await super().__call__(scope, receive, send)
  File "/usr/local/lib/python3.8/site-packages/starlette/applications.py", line 112, in __call__
    await self.middleware_stack(scope, receive, send)
  File "/usr/local/lib/python3.8/site-packages/starlette/middleware/errors.py", line 181, in __call__
    raise exc from None
  File "/usr/local/lib/python3.8/site-packages/starlette/middleware/errors.py", line 159, in __call__
    await self.app(scope, receive, _send)
  File "/usr/local/lib/python3.8/site-packages/starlette/exceptions.py", line 82, in __call__
    raise exc from None
  File "/usr/local/lib/python3.8/site-packages/starlette/exceptions.py", line 71, in __call__
    await self.app(scope, receive, sender)
  File "/usr/local/lib/python3.8/site-packages/starlette/routing.py", line 580, in __call__
    await route.handle(scope, receive, send)
  File "/usr/local/lib/python3.8/site-packages/starlette/routing.py", line 241, in handle
    await self.app(scope, receive, send)
  File "/usr/local/lib/python3.8/site-packages/starlette/routing.py", line 52, in app
    response = await func(request)
  File "/usr/local/lib/python3.8/site-packages/fastapi/routing.py", line 216, in app
    raw_response = await run_endpoint_function(
  File "/usr/local/lib/python3.8/site-packages/fastapi/routing.py", line 151, in run_endpoint_function
    return await run_in_threadpool(dependant.call, **values)
  File "/usr/local/lib/python3.8/site-packages/starlette/concurrency.py", line 40, in run_in_threadpool
    return await loop.run_in_executor(None, func, *args)
  File "/usr/local/lib/python3.8/concurrent/futures/thread.py", line 57, in run
    result = self.fn(*self.args, **self.kwargs)
  File "/app/./routes/user.py", line 26, in get_users
    return conn.execute(users.select()).fetchall()
  File "/usr/local/lib/python3.8/site-packages/sqlalchemy/engine/base.py", line 1262, in execute
    return meth(self, multiparams, params, _EMPTY_EXECUTION_OPTS)
  File "/usr/local/lib/python3.8/site-packages/sqlalchemy/sql/elements.py", line 323, in _execute_on_connection
    return connection._execute_clauseelement(
  File "/usr/local/lib/python3.8/site-packages/sqlalchemy/engine/base.py", line 1451, in _execute_clauseelement
    ret = self._execute_context(
  File "/usr/local/lib/python3.8/site-packages/sqlalchemy/engine/base.py", line 1813, in _execute_context
    self._handle_dbapi_exception(
  File "/usr/local/lib/python3.8/site-packages/sqlalchemy/engine/base.py", line 1994, in _handle_dbapi_exception
    util.raise_(
  File "/usr/local/lib/python3.8/site-packages/sqlalchemy/util/compat.py", line 207, in raise_
    raise exception
  File "/usr/local/lib/python3.8/site-packages/sqlalchemy/engine/base.py", line 1770, in _execute_context
    self.dialect.do_execute(
  File "/usr/local/lib/python3.8/site-packages/sqlalchemy/engine/default.py", line 717, in do_execute
    cursor.execute(statement, parameters)
sqlalchemy.exc.ProgrammingError: (psycopg2.errors.UndefinedTable) relation "users" does not exist
LINE 2: FROM users
             ^

[SQL: SELECT users.id, users.name, users.email, users.password 
FROM users]
(Background on this error at: http://sqlalche.me/e/14/f405)
INFO:     10.42.0.42:41066 - "GET /users HTTP/1.1" 500 Internal Server Error
ERROR:    Exception in ASGI application
Traceback (most recent call last):
  File "/usr/local/lib/python3.8/site-packages/uvicorn/protocols/http/h11_impl.py", line 369, in run_asgi
    result = await app(self.scope, self.receive, self.send)
  File "/usr/local/lib/python3.8/site-packages/uvicorn/middleware/proxy_headers.py", line 59, in __call__
    return await self.app(scope, receive, send)
  File "/usr/local/lib/python3.8/site-packages/fastapi/applications.py", line 199, in __call__
    await super().__call__(scope, receive, send)
  File "/usr/local/lib/python3.8/site-packages/starlette/applications.py", line 112, in __call__
    await self.middleware_stack(scope, receive, send)
  File "/usr/local/lib/python3.8/site-packages/starlette/middleware/errors.py", line 181, in __call__
    raise exc from None
  File "/usr/local/lib/python3.8/site-packages/starlette/middleware/errors.py", line 159, in __call__
    await self.app(scope, receive, _send)
  File "/usr/local/lib/python3.8/site-packages/starlette/exceptions.py", line 82, in __call__
    raise exc from None
  File "/usr/local/lib/python3.8/site-packages/starlette/exceptions.py", line 71, in __call__
    await self.app(scope, receive, sender)
  File "/usr/local/lib/python3.8/site-packages/starlette/routing.py", line 580, in __call__
    await route.handle(scope, receive, send)
  File "/usr/local/lib/python3.8/site-packages/starlette/routing.py", line 241, in handle
    await self.app(scope, receive, send)
  File "/usr/local/lib/python3.8/site-packages/starlette/routing.py", line 52, in app
    response = await func(request)
  File "/usr/local/lib/python3.8/site-packages/fastapi/routing.py", line 216, in app
    raw_response = await run_endpoint_function(
  File "/usr/local/lib/python3.8/site-packages/fastapi/routing.py", line 151, in run_endpoint_function
    return await run_in_threadpool(dependant.call, **values)
  File "/usr/local/lib/python3.8/site-packages/starlette/concurrency.py", line 40, in run_in_threadpool
    return await loop.run_in_executor(None, func, *args)
  File "/usr/local/lib/python3.8/concurrent/futures/thread.py", line 57, in run
    result = self.fn(*self.args, **self.kwargs)
  File "/app/./routes/user.py", line 26, in get_users
    return conn.execute(users.select()).fetchall()
  File "/usr/local/lib/python3.8/site-packages/sqlalchemy/engine/base.py", line 1262, in execute
    return meth(self, multiparams, params, _EMPTY_EXECUTION_OPTS)
  File "/usr/local/lib/python3.8/site-packages/sqlalchemy/sql/elements.py", line 323, in _execute_on_connection
    return connection._execute_clauseelement(
  File "/usr/local/lib/python3.8/site-packages/sqlalchemy/engine/base.py", line 1451, in _execute_clauseelement
    ret = self._execute_context(
  File "/usr/local/lib/python3.8/site-packages/sqlalchemy/engine/base.py", line 1813, in _execute_context
    self._handle_dbapi_exception(
  File "/usr/local/lib/python3.8/site-packages/sqlalchemy/engine/base.py", line 1994, in _handle_dbapi_exception
    util.raise_(
  File "/usr/local/lib/python3.8/site-packages/sqlalchemy/util/compat.py", line 207, in raise_
    raise exception
  File "/usr/local/lib/python3.8/site-packages/sqlalchemy/engine/base.py", line 1770, in _execute_context
    self.dialect.do_execute(
  File "/usr/local/lib/python3.8/site-packages/sqlalchemy/engine/default.py", line 717, in do_execute
    cursor.execute(statement, parameters)
sqlalchemy.exc.ProgrammingError: (psycopg2.errors.UndefinedTable) relation "users" does not exist
LINE 2: FROM users
             ^

[SQL: SELECT users.id, users.name, users.email, users.password 
FROM users]
(Background on this error at: http://sqlalche.me/e/14/f405)



